Workbook

Sheet Dashboard_Squadra
A1: Dashboard Squadra - SG Arese 2025-26
A2: Stagione completa su 18 partite. Statistiche dettagliate disponibili su 16 partite con video.
A4: Partite | C4: Vittorie | E4: Pareggi | G4: Sconfitte
A5: 18 | C5: 13 | E5: 1 | G5: 4
A6: Gol fatti | C6: Gol subiti | E6: Diff. reti | G6: Media GF
A7: 232 | C7: 182 | E7: 50 | G7: 12.888889
A8: Media GS
A9: 10.111111
A11: Split Squadra | I11: Partite senza statistiche
A12: Split | B12: Partite | C12: V | D12: N | E12: P | F12: GF | G12: GS | I12: giornata | J12: data | K12: avversario | L12: casa_trasferta | M12: arese_gol | N12: avversario_gol
A13: Casa | B13: 9 | C13: 6 | D13: 0 | E13: 3 | F13: 112 | G13: 92 | I13: 1 | J13: 2026-01-10 | K13: Project Sport | L13: Casa | M13: 13 | N13: 10
A14: Trasferta | B14: 9 | C14: 7 | D14: 1 | E14: 1 | F14: 120 | G14: 90 | I14: 12 | J14: 2026-03-28 | K14: CN Sestri | L14: Trasferta | M14: 8 | N14: 8
A15: Andata | B15: 9 | C15: 5 | D15: 0 | E15: 4 | F15: 103 | G15: 97
A16: Ritorno | B16: 9 | C16: 8 | D16: 1 | E16: 0 | F16: 129 | G16: 85
A72: Note
A73: Risultati: 18 partite. Statistiche dettagliate: 16 partite. Quarti disponibili solo dove registrati nel foglio partita.
A74: Il confronto con le altre squadre usa tutto il calendario del girone ricostruito dal file HTML.

Sheet _Dashboard_Data
A1: giornata | B1: GF | C1: GS
A2: 1 | B2: 13 | C2: 10
A3: 2 | B3: 14 | C3: 11
A4: 3 | B4: 15 | C4: 10
A5: 4 | B5: 13 | C5: 10
A6: 5 | B6: 11 | C6: 13
A7: 6 | B7: 7 | C7: 13
A8: 7 | B8: 10 | C8: 11
A9: 8 | B9: 12 | C9: 9
A10: 9 | B10: 8 | C10: 10
A11: 10 | B11: 23 | C11: 8
A12: 11 | B12: 16 | C12: 12
A13: 12 | B13: 8 | C13: 8
... A19: 18 | B19: 15 | C19: 8
A22: Split | B22: Partite | C22: V | D22: N | E22: P | F22: GF | G22: GS
A23: Casa | B23: 9 | C23: 6 | D23: 0 | E23: 3 | F23: 112 | G23: 92
A24: Trasferta | B24: 9 | C24: 7 | D24: 1 | E24: 1 | F24: 120 | G24: 90
A25: Andata | B25: 9 | C25: 5 | D25: 0 | E25: 4 | F25: 103 | G25: 97
A26: Ritorno | B26: 9 | C26: 8 | D26: 1 | E26: 0 | F26: 129 | G26: 85
A29: Quarto | B29: GF Arese | C29: GS Arese
A30: Q1 | B30: 36 | C30: 22
A31: Q2 | B31: 36 | C31: 28
A32: Q3 | B32: 41 | C32: 26
A33: Q4 | B33: 37 | C33: 30
A36: Rank | B36: Squadra | C36: Partite | D36: V | E36: N | F36: P | G36: GF | H36: GS | I36: DR | J36: Punti
A37: 1 | B37: Onda Blu Dalmine | C37: 18 | D37: 14 | E37: 1 | F37: 3 | G37: 266 | H37: 163 | I37: 103 | J37: 43
A38: 2 | B38: Bocconi Sport Team | C38: 18 | D38: 13 | E38: 2 | F38: 3 | G38: 251 | H38: 200 | I38: 51 | J38: 41
A39: 3 | B39: SG Sport Arese | C39: 18 | D39: 13 | E39: 1 | F39: 4 | G39: 232 | H39: 182 | I39: 50 | J39: 40
A40: 4 | B40: Busto PN | C40: 18 | D40: 11 | E40: 1 | F40: 6 | G40: 240 | H40: 206 | I40: 34 | J40: 34
A41: 5 | B41: WP Novara | C41: 18 | D41: 10 | E41: 1 | F41: 7 | G41: 209 | H41: 205 | I41: 4 | J41: 31
A42: 6 | B42: SG Andrea Doria | C42: 18 | D42: 8 | E42: 3 | F42: 7 | G42: 233 | H42: 205 | I42: 28 | J42: 27
A43: 7 | B43: PN Como | C43: 18 | D43: 4 | E43: 2 | F43: 12 | G43: 203 | H43: 245 | I43: -42 | J43: 14
A44: 8 | B44: CN Sestri | C44: 18 | D44: 4 | E44: 2 | F44: 12 | G44: 161 | H44: 214 | I44: -53 | J44: 14
A45: 9 | B45: PN Milano 1 | C45: 18 | D45: 4 | E45: 1 | F45: 13 | G45: 199 | H45: 275 | I45: -76 | J45: 13
A46: 10 | B46: Project Sport | C46: 18 | D46: 2 | E46: 0 | F46: 16 | G46: 190 | H46: 289 | I46: -99 | J46: 6
A49: giornata | B49: Bocconi Sport Team | C49: Busto PN | D49: Onda Blu Dalmine | E49: SG Sport Arese | F49: WP Novara
A50: 1 | B50: 0 | C50: 3 | D50: 3 | E50: 3 | F50: 3
A51: 2 | B51: 3 | C51: 6 | D51: 6 | E51: 6 | F51: 6
A52: 3 | B52: 4 | C52: 6 | D52: 9 | E52: 9 | F52: 9
A53: 4 | B53: 4 | C53: 6 | D53: 12 | E53: 12 | F53: 12
...

Sheet Dashboard_Giocatori
A1: Dashboard Giocatori - SG Arese 2025-26
A2: Lettura rapida delle performance individuali: ranking offensivi, valutazione, ruoli, mano e jolly.
A4: Top Marcatori | F4: Top Assist | J4: Top % Tiro
A5: giocatore | B5: gol_tot | F5: giocatore | G5: assist_tot | J5: giocatore | K5: pct_tiri_media | L5: pct_tiri_stagionale | M5: tiri_tot
A6: ZENO | B6: 57 | F6: CRIVE L. | G6: 20 | J6: ZENO | K6: 0.500387 | L6: 0.483051 | M6: 118
A7: BOBBY | B7: 36 | F7: BOBBY | G7: 19 | J7: STERI | K7: 0.458333 | L7: 0.575758 | M7: 33
A8: CRIVE A. | B8: 22 | F8: BIGA | G8: 17 | J8: BOBBY | K8: 0.401337 | L8: 0.423529 | M8: 85
A9: STERI | B9: 19 | F9: BOBBOX | G9: 14 | J9: BIGA | K9: 0.391026 | L9: 0.484848 | M9: 33
A10: BIGA | B10: 16 | F10: SOLDI | G10: 14 | J10: CRIVE A. | K10: 0.382143 | L10: 0.431373 | M10: 51
A11: GULLO | B11: 16 | F11: NOA | G11: 12 | J11: DONATO | K11: 0.373299 | L11: 0.375 | M11: 40
A12: DONATO | B12: 15 | F12: CRIVE A. | G12: 11 | J12: POPOVIC | K12: 0.358974 | L12: 0.407407 | M12: 27
A13: POPOVIC | B13: 11 | F13: DONATO | G13: 7 | J13: GULLO | K13: 0.351361 | L13: 0.347826 | M13: 46
A16: Ruoli Base | H16: Mano | L16: Jolly
A17: Ruolo | B17: Giocatori | C17: Gol | D17: Assist | E17: Indice_Valutazione | F17: Valutazione_Grezza | H17: Mano | I17: Giocatori | J17: Gol | K17: Assist | L17: Jolly | M17: Giocatori | N17: Gol | O17: Assist | P17: Indice_Valutazione | Q17: Valutazione_Grezza
A18: 1-2 - mano-cattiva | B18: 5 | C18: 30 | D18: 54 | E18: 24.82 | F18: 297.5 | H18: D | I18: 15 | J18: 196 | K18: 130 | L18: SI | M18: 4 | N18: 90 | O18: 54 | P18: 65.49 | Q18: 693.5
A19: 3 - marcatore del centro | B19: 3 | C19: 19 | D19: 22 | E19: 17.38 | F19: 116 | H19: S | I19: 1 | J19: 15 | K19: 7 | L19: NO | M19: 12 | N19: 121 | O19: 83 | P19: 27.0375 | Q19: 788.5
A20: 4-5 - mano-buona | B20: 5 | C20: 120 | D20: 46 | E20: 53.536 | F20: 699.5
A21: 6 - centroboa | B21: 3 | C21: 42 | D21: 15 | E21: 47.496667 | F21: 369
A25: Top Valutazione
A26: giocatore | B26: indice_valutazione_0_100 | C26: valutazione_grezza_totale
A27: BOBBY | B27: 100 | C27: 270
A28: ZENO | B28: 98.39 | C28: 265.5
A29: CRIVE A. | B29: 73.21 | C29: 195
A30: STERI | B30: 62.32 | C30: 164.5
A31: BIGA | B31: 45.36 | C31: 117
A32: DONATO | B32: 45.18 | C32: 116.5
A33: GULLO | B33: 43.39 | C33: 111.5
A34: NOA | B34: 33.39 | C34: 83.5
A68: Note
A69: Le metriche di efficienza e media sono da leggere con soglia minima consigliata di 3 partite nel foglio statistico.
A70: La dashboard giocatori e' costruita sulle 16 partite con statistiche video disponibili.

Sheet _Dashboard_Giocatori_Data
A1: giocatore | B1: gol_tot
A2: ZENO | B2: 57
A3: BOBBY | B3: 36
A4: CRIVE A. | B4: 22
A5: STERI | B5: 19
A6: BIGA | B6: 16
A7: GULLO | B7: 16
A8: DONATO | B8: 15
A9: POPOVIC | B9: 11
A12: giocatore | B12: assist_tot
A13: CRIVE L. | B13: 20
A14: BOBBY | B14: 19
A15: BIGA | B15: 17
A16: BOBBOX | B16: 14
A17: SOLDI | B17: 14
A18: NOA | B18: 12
A19: CRIVE A. | B19: 11
A20: DONATO | B20: 7
A23: giocatore | B23: indice_valutazione_0_100 | C23: valutazione_grezza_totale
A24: BOBBY | B24: 100 | C24: 270
A25: ZENO | B25: 98.39 | C25: 265.5
A26: CRIVE A. | B26: 73.21 | C26: 195
A27: STERI | B27: 62.32 | C27: 164.5
A28: BIGA | B28: 45.36 | C28: 117
A29: DONATO | B29: 45.18 | C29: 116.5
A30: GULLO | B30: 43.39 | C30: 111.5
A31: NOA | B31: 33.39 | C31: 83.5
A34: Ruolo | B34: Giocatori | C34: Gol | D34: Assist | E34: Indice_Valutazione | F34: Valutazione_Grezza
A35: 1-2 - mano-cattiva | B35: 5 | C35: 30 | D35: 54 | E35: 24.82 | F35: 297.5
A36: 3 - marcatore del centro | B36: 3 | C36: 19 | D36: 22 | E36: 17.38 | F36: 116
A37: 4-5 - mano-buona | B37: 5 | C37: 120 | D37: 46 | E37: 53.536 | F37: 699.5
A38: 6 - centroboa | B38: 3 | C38: 42 | D38: 15 | E38: 47.496667 | F38: 369
A41: Mano | B41: Giocatori | C41: Gol | D41: Assist | E41: Indice_Valutazione | F41: Valutazione_Grezza
A42: D | B42: 15 | C42: 196 | D42: 130 | E42: 36.082 | F42: 1365.5
A43: S | B43: 1 | C43: 15 | D43: 7 | E43: 45.18 | F43: 116.5
A46: Jolly | B46: Giocatori | C46: Gol | D46: Assist | E46: Indice_Valutazione | F46: Valutazione_Grezza
A47: SI | B47: 4 | C47: 90 | D47: 54 | E47: 65.49 | F47: 693.5
A48: NO | B48: 12 | C48: 121 | D48: 83 | E48: 27.0375 | F48: 788.5
A51: giocatore | B51: pct_tiri_media | C51: pct_tiri_stagionale | D51: tiri_tot
A52: ZENO | B52: 0.500387 | C52: 0.483051 | D52: 118
...

Sheet Dashboard_Portieri
A1: Dashboard Portieri - SG Arese 2025-26
A2: Focus dedicato ai portieri: volume parate, efficienza, gol subiti e valutazione sul campione video disponibile.
A4: Panoramica Portieri
A5: Portiere | B5: Mano | C5: Partite | D5: Partite giocate stimate | E5: Parate | F5: Gol subiti | G5: % parate media | H5: Valutazione grezza totale | I5: Valutazione grezza media | J5: Indice 0-100
A6: FRANCHI | B6: D | C6: 3 | D6: 2 | E6: 4 | F6: 5 | G6: 0.45 | H6: 3 | I6: 1.5 | J6: 100
A7: LUCA BOLO | B7: D | C7: 14 | D7: 9 | E7: 54 | F7: 73 | G7: 0.372448 | H7: -47.9 | I7: -5.322222 | J7: 0
A8: SANTA | B8: S | C8: 16 | D8: 12 | E8: 82 | F8: 86 | G8: 0.43914 | H8: -6 | I8: -0.5 | J8: 82.32
A12: Parate Totali | E12: % Parate | I12: Gol Subiti
A13: giocatore | B13: parata_tot | E13: giocatore | F13: pct_parate_media | G13: partite_giocate_stimate | I13: giocatore | J13: gol_subito_tot | K13: partite_giocate_stimate
A14: SANTA | B14: 82 | E14: FRANCHI | F14: 0.45 | G14: 2 | I14: FRANCHI | J14: 5 | K14: 2
A15: LUCA BOLO | B15: 54 | E15: SANTA | F15: 0.43914 | G15: 12 | I15: LUCA BOLO | J15: 73 | K15: 9
A16: FRANCHI | B16: 4 | E16: LUCA BOLO | F16: 0.372448 | G16: 9 | I16: SANTA | J16: 86 | K16: 12
A19: Valutazione
A20: giocatore | B20: indice_valutazione_0_100 | C20: valutazione_grezza_totale | D20: valutazione_grezza_media
A21: FRANCHI | B21: 100 | C21: 3 | D21: 1.5
A22: SANTA | B22: 82.32 | C22: -6 | D22: -0.5
A23: LUCA BOLO | B23: 0 | C23: -47.9 | D23: -5.322222
A62: Note
A63: Per i portieri, una partita e' considerata giocata se ha almeno una tra parata > 0 o gol_subito > 0.
A64: Le medie principali dei portieri usano le partite_giocate_stimate; la % parate media usa solo le righe con partita giocata stimata.

Sheet _Dashboard_Portieri_Data
A1: Portiere | B1: Mano | C1: Partite | D1: Partite giocate stimate | E1: Parate | F1: Gol subiti | G1: % parate media | H1: Valutazione grezza totale | I1: Valutazione grezza media | J1: Indice 0-100
A2: FRANCHI | B2: D | C2: 3 | D2: 2 | E2: 4 | F2: 5 | G2: 0.45 | H2: 3 | I2: 1.5 | J2: 100
A3: LUCA BOLO | B3: D | C3: 14 | D3: 9 | E3: 54 | F3: 73 | G3: 0.372448 | H3: -47.9 | I3: -5.322222 | J3: 0
A4: SANTA | B4: S | C4: 16 | D4: 12 | E4: 82 | F4: 86 | G4: 0.43914 | H4: -6 | I4: -0.5 | J4: 82.32
A7: giocatore | B7: parata_tot
A8: SANTA | B8: 82
A9: LUCA BOLO | B9: 54
A10: FRANCHI | B10: 4
A13: giocatore | B13: pct_parate_media | C13: partite_giocate_stimate
A14: FRANCHI | B14: 0.45 | C14: 2
A15: SANTA | B15: 0.43914 | C15: 12
A16: LUCA BOLO | B16: 0.372448 | C16: 9
A19: giocatore | B19: gol_subito_tot | C19: partite_giocate_stimate
A20: FRANCHI | B20: 5 | C20: 2
A21: LUCA BOLO | B21: 73 | C21: 9
A22: SANTA | B22: 86 | C22: 12
A25: giocatore | B25: indice_valutazione_0_100 | C25: valutazione_grezza_totale | D25: valutazione_grezza_media
A26: FRANCHI | B26: 100 | C26: 3 | D26: 1.5
A27: SANTA | B27: 82.32 | C27: -6 | D27: -0.5
A28: LUCA BOLO | B28: 0 | C28: -47.9 | D28: -5.322222

Sheet Confronto_Giocatori
A1: Confronto Giocatori - SG Arese 2025-26
A2: Seleziona uno o due giocatori per confrontare statistiche aggregate e dettaglio partita-per-partita.
A4: Giocatori di Movimento
A5: Giocatore A | B5: BIGA | C5: Giocatore B | D5: BOBBOX
A8: Metrica | B8: Giocatore A | C8: Giocatore B | D8: Delta A-B | F8: Confronto offensivo
A9: Ruolo | B9: {=IF($B$5="","",_xlfn.XLOOKUP($B$5,'_Confronto_Data'!$F$2:$F$17,'_Confronto_Data'!$L$2:$L$17,""))} -> 0 | C9: {=IF($D$5="","",_xlfn.XLOOKUP($D$5,'_Confronto_Data'!$F$2:$F$17,'_Confronto_Data'!$L$2:$L$17,""))} -> 0 | F9: Metrica | G9: A | H9: B
A10: Mano | B10: {=IF($B$5="","",_xlfn.XLOOKUP($B$5,'_Confronto_Data'!$F$2:$F$17,'_Confronto_Data'!$J$2:$J$17,""))} -> 0 | C10: {=IF($D$5="","",_xlfn.XLOOKUP($D$5,'_Confronto_Data'!$F$2:$F$17,'_Confronto_Data'!$J$2:$J$17,""))} -> 0 | F10: Gol | G10: =B13 -> 0 | H10: =C13 -> 0
A11: Jolly | B11: {=IF($B$5="","",_xlfn.XLOOKUP($B$5,'_Confronto_Data'!$F$2:$F$17,'_Confronto_Data'!$M$2:$M$17,""))} -> 0 | C11: {=IF($D$5="","",_xlfn.XLOOKUP($D$5,'_Confronto_Data'!$F$2:$F$17,'_Confronto_Data'!$M$2:$M$17,""))} -> 0 | F11: Assist | G11: =B15 -> 0 | H11: =C15 -> 0
A12: Partite | B12: {=IF($B$5="","",_xlfn.XLOOKUP($B$5,'_Confronto_Data'!$F$2:$F$17,'_Confronto_Data'!$P$2:$P$17,""))} -> 0 | C12: {=IF($D$5="","",_xlfn.XLOOKUP($D$5,'_Confronto_Data'!$F$2:$F$17,'_Confronto_Data'!$P$2:$P$17,""))} -> 0 | D12: =IF(OR(B12="",C12=""),"",B12-C12) -> 0 | F12: Tiri | G12: =B17 -> 0 | H12: =C17 -> 0
A13: Gol | B13: {=IF($B$5="","",_xlfn.XLOOKUP($B$5,'_Confronto_Data'!$F$2:$F$17,'_Confronto_Data'!$R$2:$R$17,""))} -> 0 | C13: {=IF($D$5="","",_xlfn.XLOOKUP($D$5,'_Confronto_Data'!$F$2:$F$17,'_Confronto_Data'!$R$2:$R$17,""))} -> 0 | D13: =IF(OR(B13="",C13=""),"",B13-C13) -> 0
A14: Gol/partita | B14: {=IF($B$5="","",_xlfn.XLOOKUP($B$5,'_Confronto_Data'!$F$2:$F$17,'_Confronto_Data'!$S$2:$S$17,""))} -> 0 | C14: {=IF($D$5="","",_xlfn.XLOOKUP($D$5,'_Confronto_Data'!$F$2:$F$17,'_Confronto_Data'!$S$2:$S$17,""))} -> 0 | D14: =IF(OR(B14="",C14=""),"",B14-C14) -> 0
A15: Assist | B15: {=IF($B$5="","",_xlfn.XLOOKUP($B$5,'_Confronto_Data'!$F$2:$F$17,'_Confronto_Data'!$T$2:$T$17,""))} -> 0 | C15: {=IF($D$5="","",_xlfn.XLOOKUP($D$5,'_Confronto_Data'!$F$2:$F$17,'_Confronto_Data'!$T$2:$T$17,""))} -> 0 | D15: =IF(OR(B15="",C15=""),"",B15-C15) -> 0
A16: Assist/partita | B16: {=IF($B$5="","",_xlfn.XLOOKUP($B$5,'_Confronto_Data'!$F$2:$F$17,'_Confronto_Data'!$U$2:$U$17,""))} -> 0 | C16: {=IF($D$5="","",_xlfn.XLOOKUP($D$5,'_Confronto_Data'!$F$2:$F$17,'_Confronto_Data'!$U$2:$U$17,""))} -> 0 | D16: =IF(OR(B16="",C16=""),"",B16-C16) -> 0
A17: Tiri | B17: {=IF($B$5="","",_xlfn.XLOOKUP($B$5,'_Confronto_Data'!$F$2:$F$17,'_Confronto_Data'!$V$2:$V$17,""))} -> 0 | C17: {=IF($D$5="","",_xlfn.XLOOKUP($D$5,'_Confronto_Data'!$F$2:$F$17,'_Confronto_Data'!$V$2:$V$17,""))} -> 0 | D17: =IF(OR(B17="",C17=""),"",B17-C17) -> 0
A18: % tiro media | B18: {=IF($B$5="","",_xlfn.XLOOKUP($B$5,'_Confronto_Data'!$F$2:$F$17,'_Confronto_Data'!$AS$2:$AS$17,""))} -> 0 | C18: {=IF($D$5="","",_xlfn.XLOOKUP($D$5,'_Confronto_Data'!$F$2:$F$17,'_Confronto_Data'!$AS$2:$AS$17,""))} -> 0 | D18: =IF(OR(B18="",C18=""),"",B18-C18) -> 0
A19: % tiro stagionale | B19: {=IF($B$5="","",_xlfn.XLOOKUP($B$5,'_Confronto_Data'!$F$2:$F$17,'_Confronto_Data'!$AT$2:$AT$17,""))} -> 0 | C19: {=IF($D$5="","",_xlfn.XLOOKUP($D$5,'_Confronto_Data'!$F$2:$F$17,'_Confronto_Data'!$AT$2:$AT$17,""))} -> 0 | D19: =IF(OR(B19="",C19=""),"",B19-C19) -> 0
A20: Palle rubate | B20: {=IF($B$5="","",_xlfn.XLOOKUP($B$5,'_Confronto_Data'!$F$2:$F$17,'_Confronto_Data'!$X$2:$X$17,""))} -> 0 | C20: {=IF($D$5="","",_xlfn.XLOOKUP($D$5,'_Confronto_Data'!$F$2:$F$17,'_Confronto_Data'!$X$2:$X$17,""))} -> 0 | D20: =IF(OR(B20="",C20=""),"",B20-C20) -> 0
A21: Palle perse | B21: {=IF($B$5="","",_xlfn.XLOOKUP($B$5,'_Confronto_Data'!$F$2:$F$17,'_Confronto_Data'!$AJ$2:$AJ$17,""))} -> 0 | C21: {=IF($D$5="","",_xlfn.XLOOKUP($D$5,'_Confronto_Data'!$F$2:$F$17,'_Confronto_Data'!$AJ$2:$AJ$17,""))} -> 0 | D21: =IF(OR(B21="",C21=""),"",B21-C21) -> 0
A22: ET+ | B22: {=IF($B$5="","",_xlfn.XLOOKUP($B$5,'_Confronto_Data'!$F$2:$F$17,'_Confronto_Data'!$Z$2:$Z$17,""))} -> 0 | C22: {=IF($D$5="","",_xlfn.XLOOKUP($D$5,'_Confronto_Data'!$F$2:$F$17,'_Confronto_Data'!$Z$2:$Z$17,""))} -> 0 | D22: =IF(OR(B22="",C22=""),"",B22-C22) -> 0
A23: ET- | B23: {=IF($B$5="","",_xlfn.XLOOKUP($B$5,'_Confronto_Data'!$F$2:$F$17,'_Confronto_Data'!$AF$2:$AF$17,""))} -> 0 | C23: {=IF($D$5="","",_xlfn.XLOOKUP($D$5,'_Confronto_Data'!$F$2:$F$17,'_Confronto_Data'!$AF$2:$AF$17,""))} -> 0 | D23: =IF(OR(B23="",C23=""),"",B23-C23) -> 0
A24: TR+ | B24: {=IF($B$5="","",_xlfn.XLOOKUP($B$5,'_Confronto_Data'!$F$2:$F$17,'_Confronto_Data'!$AB$2:$AB$17,""))} -> 0 | C24: {=IF($D$5="","",_xlfn.XLOOKUP($D$5,'_Confronto_Data'!$F$2:$F$17,'_Confronto_Data'!$AB$2:$AB$17,""))} -> 0 | D24: =IF(OR(B24="",C24=""),"",B24-C24) -> 0
A25: TR- | B25: {=IF($B$5="","",_xlfn.XLOOKUP($B$5,'_Confronto_Data'!$F$2:$F$17,'_Confronto_Data'!$AH$2:$AH$17,""))} -> 0 | C25: {=IF($D$5="","",_xlfn.XLOOKUP($D$5,'_Confronto_Data'!$F$2:$F$17,'_Confronto_Data'!$AH$2:$AH$17,""))} -> 0 | D25: =IF(OR(B25="",C25=""),"",B25-C25) -> 0
A26: Controfalli | B26: {=IF($B$5="","",_xlfn.XLOOKUP($B$5,'_Confronto_Data'!$F$2:$F$17,'_Confronto_Data'!$AN$2:$AN$17,""))} -> 0 | C26: {=IF($D$5="","",_xlfn.XLOOKUP($D$5,'_Confronto_Data'!$F$2:$F$17,'_Confronto_Data'!$AN$2:$AN$17,""))} -> 0 | D26: =IF(OR(B26="",C26=""),"",B26-C26) -> 0
A27: Errori | B27: {=IF($B$5="","",_xlfn.XLOOKUP($B$5,'_Confronto_Data'!$F$2:$F$17,'_Confronto_Data'!$AP$2:$AP$17,""))} -> 0 | C27: {=IF($D$5="","",_xlfn.XLOOKUP($D$5,'_Confronto_Data'!$F$2:$F$17,'_Confronto_Data'!$AP$2:$AP$17,""))} -> 0 | D27: =IF(OR(B27="",C27=""),"",B27-C27) -> 0
A28: Val. grezza tot | B28: {=IF($B$5="","",_xlfn.XLOOKUP($B$5,'_Confronto_Data'!$F$2:$F$17,'_Confronto_Data'!$AW$2:$AW$17,""))} -> 0 | C28: {=IF($D$5="","",_xlfn.XLOOKUP($D$5,'_Confronto_Data'!$F$2:$F$17,'_Confronto_Data'!$AW$2:$AW$17,""))} -> 0 | D28: =IF(OR(B28="",C28=""),"",B28-C28) -> 0
A29: Val. grezza media | B29: {=IF($B$5="","",_xlfn.XLOOKUP($B$5,'_Confronto_Data'!$F$2:$F$17,'_Confronto_Data'!$AY$2:$AY$17,""))} -> 0 | C29: {=IF($D$5="","",_xlfn.XLOOKUP($D$5,'_Confronto_Data'!$F$2:$F$17,'_Confronto_Data'!$AY$2:$AY$17,""))} -> 0 | D29: =IF(OR(B29="",C29=""),"",B29-C29) -> 0
A30: Indice 0-100 | B30: {=IF($B$5="","",_xlfn.XLOOKUP($B$5,'_Confronto_Data'!$F$2:$F$17,'_Confronto_Data'!$AZ$2:$AZ$17,""))} -> 0 | C30: {=IF($D$5="","",_xlfn.XLOOKUP($D$5,'_Confronto_Data'!$F$2:$F$17,'_Confronto_Data'!$AZ$2:$AZ$17,""))} -> 0 | D30: =IF(OR(B30="",C30=""),"",B30-C30) -> 0
A31: Dettaglio movimento partita-per-partita
A32: G | B32: Data | C32: Avversario | D32: Casa/Trasf | E32: A Gol | F32: A Ast | G32: A Tiri | H32: A Val | I32: B Gol | J32: B Ast | K32: B Tiri | L32: B Val
A33: 1 | B33: {=_xlfn.XLOOKUP(A33,'_Confronto_Data'!$FO$2:$FO$19,'_Confronto_Data'!$FP$2:$FP$19,"")} -> 0 | C33: {=_xlfn.XLOOKUP(A33,'_Confronto_Data'!$FO$2:$FO$19,'_Confronto_Data'!$FQ$2:$FQ$19,"")} -> 0 | D33: {=_xlfn.XLOOKUP(A33,'_Confronto_Data'!$FO$2:$FO$19,'_Confronto_Data'!$FR$2:$FR$19,"")} -> 0 | E33: =IF($B$5="","",SUMIFS('_Confronto_Data'!$DQ$2:$DQ$195,'_Confronto_Data'!$DL$2:$DL$195,$B$5,'_Confronto_Data'!$DM$2:$DM$195,$A33)) -> 0 | F33: =IF($B$5="","",SUMIFS('_Confronto_Data'!$DR$2:$DR$195,'_Confronto_Data'!$DL$2:$DL$195,$B$5,'_Confronto_Data'!$DM$2:$DM$195,$A33)) -> 0 | G33: =IF($B$5="","",SUMIFS('_Confronto_Data'!$DS$2:$DS$195,'_Confronto_Data'!$DL$2:$DL$195,$B$5,'_Confronto_Data'!$DM$2:$DM$195,$A33)) -> 0 | H33: =IF($B$5="","",SUMIFS('_Confronto_Data'!$EC$2:$EC$195,'_Confronto_Data'!$DL$2:$DL$195,$B$5,'_Confronto_Data'!$DM$2:$DM$195,$A33)) -> 0 | I33: =IF($D$5="","",SUMIFS('_Confronto_Data'!$DQ$2:$DQ$195,'_Confronto_Data'!$DL$2:$DL$195,$D$5,'_Confronto_Data'!$DM$2:$DM$195,$A33)) -> 0 | J33: =IF($D$5="","",SUMIFS('_Confronto_Data'!$DR$2:$DR$195,'_Confronto_Data'!$DL$2:$DL$195,$D$5,'_Confronto_Data'!$DM$2:$DM$195,$A33)) -> 0 | K33: =IF($D$5="","",SUMIFS('_Confronto_Data'!$DS$2:$DS$195,'_Confronto_Data'!$DL$2:$DL$195,$D$5,'_Confronto_Data'!$DM$2:$DM$195,$A33)) -> 0 | L33: =IF($D$5="","",SUMIFS('_Confronto_Data'!$EC$2:$EC$195,'_Confronto_Data'!$DL$2:$DL$195,$D$5,'_Confronto_Data'!$DM$2:$DM$195,$A33)) -> 0
A34: 2 | B34: {=_xlfn.XLOOKUP(A34,'_Confronto_Data'!$FO$2:$FO$19,'_Confronto_Data'!$FP$2:$FP$19,"")} -> 0 | C34: {=_xlfn.XLOOKUP(A34,'_Confronto_Data'!$FO$2:$FO$19,'_Confronto_Data'!$FQ$2:$FQ$19,"")} -> 0 | D34: {=_xlfn.XLOOKUP(A34,'_Confronto_Data'!$FO$2:$FO$19,'_Confronto_Data'!$FR$2:$FR$19,"")} -> 0 | E34: =IF($B$5="","",SUMIFS('_Confronto_Data'!$DQ$2:$DQ$195,'_Confronto_Data'!$DL$2:$DL$195,$B$5,'_Confronto_Data'!$DM$2:$DM$195,$A34)) -> 0 | F34: =IF($B$5="","",SUMIFS('_Confronto_Data'!$DR$2:$DR$195,'_Confronto_Data'!$DL$2:$DL$195,$B$5,'_Confronto_Data'!$DM$2:$DM$195,$A34)) -> 0 | G34: =IF($B$5="","",SUMIFS('_Confronto_Data'!$DS$2:$DS$195,'_Confronto_Data'!$DL$2:$DL$195,$B$5,'_Confronto_Data'!$DM$2:$DM$195,$A34)) -> 0 | H34: =IF($B$5="","",SUMIFS('_Confronto_Data'!$EC$2:$EC$195,'_Confronto_Data'!$DL$2:$DL$195,$B$5,'_Confronto_Data'!$DM$2:$DM$195,$A34)) -> 0 | I34: =IF($D$5="","",SUMIFS('_Confronto_Data'!$DQ$2:$DQ$195,'_Confronto_Data'!$DL$2:$DL$195,$D$5,'_Confronto_Data'!$DM$2:$DM$195,$A34)) -> 0 | J34: =IF($D$5="","",SUMIFS('_Confronto_Data'!$DR$2:$DR$195,'_Confronto_Data'!$DL$2:$DL$195,$D$5,'_Confronto_Data'!$DM$2:$DM$195,$A34)) -> 0 | K34: =IF($D$5="","",SUMIFS('_Confronto_Data'!$DS$2:$DS$195,'_Confronto_Data'!$DL$2:$DL$195,$D$5,'_Confronto_Data'!$DM$2:$DM$195,$A34)) -> 0 | L34: =IF($D$5="","",SUMIFS('_Confronto_Data'!$EC$2:$EC$195,'_Confronto_Data'!$DL$2:$DL$195,$D$5,'_Confronto_Data'!$DM$2:$DM$195,$A34)) -> 0
A35: 3 | B35: {=_xlfn.XLOOKUP(A35,'_Confronto_Data'!$FO$2:$FO$19,'_Confronto_Data'!$FP$2:$FP$19,"")} -> 0 | C35: {=_xlfn.XLOOKUP(A35,'_Confronto_Data'!$FO$2:$FO$19,'_Confronto_Data'!$FQ$2:$FQ$19,"")} -> 0 | D35: {=_xlfn.XLOOKUP(A35,'_Confronto_Data'!$FO$2:$FO$19,'_Confronto_Data'!$FR$2:$FR$19,"")} -> 0 | E35: =IF($B$5="","",SUMIFS('_Confronto_Data'!$DQ$2:$DQ$195,'_Confronto_Data'!$DL$2:$DL$195,$B$5,'_Confronto_Data'!$DM$2:$DM$195,$A35)) -> 0 | F35: =IF($B$5="","",SUMIFS('_Confronto_Data'!$DR$2:$DR$195,'_Confronto_Data'!$DL$2:$DL$195,$B$5,'_Confronto_Data'!$DM$2:$DM$195,$A35)) -> 0 | G35: =IF($B$5="","",SUMIFS('_Confronto_Data'!$DS$2:$DS$195,'_Confronto_Data'!$DL$2:$DL$195,$B$5,'_Confronto_Data'!$DM$2:$DM$195,$A35)) -> 0 | H35: =IF($B$5="","",SUMIFS('_Confronto_Data'!$EC$2:$EC$195,'_Confronto_Data'!$DL$2:$DL$195,$B$5,'_Confronto_Data'!$DM$2:$DM$195,$A35)) -> 0 | I35: =IF($D$5="","",SUMIFS('_Confronto_Data'!$DQ$2:$DQ$195,'_Confronto_Data'!$DL$2:$DL$195,$D$5,'_Confronto_Data'!$DM$2:$DM$195,$A35)) -> 0 | J35: =IF($D$5="","",SUMIFS('_Confronto_Data'!$DR$2:$DR$195,'_Confronto_Data'!$DL$2:$DL$195,$D$5,'_Confronto_Data'!$DM$2:$DM$195,$A35)) -> 0 | K35: =IF($D$5="","",SUMIFS('_Confronto_Data'!$DS$2:$DS$195,'_Confronto_Data'!$DL$2:$DL$195,$D$5,'_Confronto_Data'!$DM$2:$DM$195,$A35)) -> 0 | L35: =IF($D$5="","",SUMIFS('_Confronto_Data'!$EC$2:$EC$195,'_Confronto_Data'!$DL$2:$DL$195,$D$5,'_Confronto_Data'!$DM$2:$DM$195,$A35)) -> 0
A36: 4 | B36: {=_xlfn.XLOOKUP(A36,'_Confronto_Data'!$FO$2:$FO$19,'_Confronto_Data'!$FP$2:$FP$19,"")} -> 0 | C36: {=_xlfn.XLOOKUP(A36,'_Confronto_Data'!$FO$2:$FO$19,'_Confronto_Data'!$FQ$2:$FQ$19,"")} -> 0 | D36: {=_xlfn.XLOOKUP(A36,'_Confronto_Data'!$FO$2:$FO$19,'_Confronto_Data'!$FR$2:$FR$19,"")} -> 0 | E36: =IF($B$5="","",SUMIFS('_Confronto_Data'!$DQ$2:$DQ$195,'_Confronto_Data'!$DL$2:$DL$195,$B$5,'_Confronto_Data'!$DM$2:$DM$195,$A36)) -> 0 | F36: =IF($B$5="","",SUMIFS('_Confronto_Data'!$DR$2:$DR$195,'_Confronto_Data'!$DL$2:$DL$195,$B$5,'_Confronto_Data'!$DM$2:$DM$195,$A36)) -> 0 | G36: =IF($B$5="","",SUMIFS('_Confronto_Data'!$DS$2:$DS$195,'_Confronto_Data'!$DL$2:$DL$195,$B$5,'_Confronto_Data'!$DM$2:$DM$195,$A36)) -> 0 | H36: =IF($B$5="","",SUMIFS('_Confronto_Data'!$EC$2:$EC$195,'_Confronto_Data'!$DL$2:$DL$195,$B$5,'_Confronto_Data'!$DM$2:$DM$195,$A36)) -> 0 | I36: =IF($D$5="","",SUMIFS('_Confronto_Data'!$DQ$2:$DQ$195,'_Confronto_Data'!$DL$2:$DL$195,$D$5,'_Confronto_Data'!$DM$2:$DM$195,$A36)) -> 0 | J36: =IF($D$5="","",SUMIFS('_Confronto_Data'!$DR$2:$DR$195,'_Confronto_Data'!$DL$2:$DL$195,$D$5,'_Confronto_Data'!$DM$2:$DM$195,$A36)) -> 0 | K36: =IF($D$5="","",SUMIFS('_Confronto_Data'!$DS$2:$DS$195,'_Confronto_Data'!$DL$2:$DL$195,$D$5,'_Confronto_Data'!$DM$2:$DM$195,$A36)) -> 0 | L36: =IF($D$5="","",SUMIFS('_Confronto_Data'!$EC$2:$EC$195,'_Confronto_Data'!$DL$2:$DL$195,$D$5,'_Confronto_Data'!$DM$2:$DM$195,$A36)) -> 0
A37: 5 | B37: {=_xlfn.XLOOKUP(A37,'_Confronto_Data'!$FO$2:$FO$19,'_Confronto_Data'!$FP$2:$FP$19,"")} -> 0 | C37: {=_xlfn.XLOOKUP(A37,'_Confronto_Data'!$FO$2:$FO$19,'_Confronto_Data'!$FQ$2:$FQ$19,"")} -> 0 | D37: {=_xlfn.XLOOKUP(A37,'_Confronto_Data'!$FO$2:$FO$19,'_Confronto_Data'!$FR$2:$FR$19,"")} -> 0 | E37: =IF($B$5="","",SUMIFS('_Confronto_Data'!$DQ$2:$DQ$195,'_Confronto_Data'!$DL$2:$DL$195,$B$5,'_Confronto_Data'!$DM$2:$DM$195,$A37)) -> 0 | F37: =IF($B$5="","",SUMIFS('_Confronto_Data'!$DR$2:$DR$195,'_Confronto_Data'!$DL$2:$DL$195,$B$5,'_Confronto_Data'!$DM$2:$DM$195,$A37)) -> 0 | G37: =IF($B$5="","",SUMIFS('_Confronto_Data'!$DS$2:$DS$195,'_Confronto_Data'!$DL$2:$DL$195,$B$5,'_Confronto_Data'!$DM$2:$DM$195,$A37)) -> 0 | H37: =IF($B$5="","",SUMIFS('_Confronto_Data'!$EC$2:$EC$195,'_Confronto_Data'!$DL$2:$DL$195,$B$5,'_Confronto_Data'!$DM$2:$DM$195,$A37)) -> 0 | I37: =IF($D$5="","",SUMIFS('_Confronto_Data'!$DQ$2:$DQ$195,'_Confronto_Data'!$DL$2:$DL$195,$D$5,'_Confronto_Data'!$DM$2:$DM$195,$A37)) -> 0 | J37: =IF($D$5="","",SUMIFS('_Confronto_Data'!$DR$2:$DR$195,'_Confronto_Data'!$DL$2:$DL$195,$D$5,'_Confronto_Data'!$DM$2:$DM$195,$A37)) -> 0 | K37: =IF($D$5="","",SUMIFS('_Confronto_Data'!$DS$2:$DS$195,'_Confronto_Data'!$DL$2:$DL$195,$D$5,'_Confronto_Data'!$DM$2:$DM$195,$A37)) -> 0 | L37: =IF($D$5="","",SUMIFS('_Confronto_Data'!$EC$2:$EC$195,'_Confronto_Data'!$DL$2:$DL$195,$D$5,'_Confronto_Data'!$DM$2:$DM$195,$A37)) -> 0
A38: 6 | B38: {=_xlfn.XLOOKUP(A38,'_Confronto_Data'!$FO$2:$FO$19,'_Confronto_Data'!$FP$2:$FP$19,"")} -> 0 | C38: {=_xlfn.XLOOKUP(A38,'_Confronto_Data'!$FO$2:$FO$19,'_Confronto_Data'!$FQ$2:$FQ$19,"")} -> 0 | D38: {=_xlfn.XLOOKUP(A38,'_Confronto_Data'!$FO$2:$FO$19,'_Confronto_Data'!$FR$2:$FR$19,"")} -> 0 | E38: =IF($B$5="","",SUMIFS('_Confronto_Data'!$DQ$2:$DQ$195,'_Confronto_Data'!$DL$2:$DL$195,$B$5,'_Confronto_Data'!$DM$2:$DM$195,$A38)) -> 0 | F38: =IF($B$5="","",SUMIFS('_Confronto_Data'!$DR$2:$DR$195,'_Confronto_Data'!$DL$2:$DL$195,$B$5,'_Confronto_Data'!$DM$2:$DM$195,$A38)) -> 0 | G38: =IF($B$5="","",SUMIFS('_Confronto_Data'!$DS$2:$DS$195,'_Confronto_Data'!$DL$2:$DL$195,$B$5,'_Confronto_Data'!$DM$2:$DM$195,$A38)) -> 0 | H38: =IF($B$5="","",SUMIFS('_Confronto_Data'!$EC$2:$EC$195,'_Confronto_Data'!$DL$2:$DL$195,$B$5,'_Confronto_Data'!$DM$2:$DM$195,$A38)) -> 0 | I38: =IF($D$5="","",SUMIFS('_Confronto_Data'!$DQ$2:$DQ$195,'_Confronto_Data'!$DL$2:$DL$195,$D$5,'_Confronto_Data'!$DM$2:$DM$195,$A38)) -> 0 | J38: =IF($D$5="","",SUMIFS('_Confronto_Data'!$DR$2:$DR$195,'_Confronto_Data'!$DL$2:$DL$195,$D$5,'_Confronto_Data'!$DM$2:$DM$195,$A38)) -> 0 | K38: =IF($D$5="","",SUMIFS('_Confronto_Data'!$DS$2:$DS$195,'_Confronto_Data'!$DL$2:$DL$195,$D$5,'_Confronto_Data'!$DM$2:$DM$195,$A38)) -> 0 | L38: =IF($D$5="","",SUMIFS('_Confronto_Data'!$EC$2:$EC$195,'_Confronto_Data'!$DL$2:$DL$195,$D$5,'_Confronto_Data'!$DM$2:$DM$195,$A38)) -> 0
A39: 7 | B39: {=_xlfn.XLOOKUP(A39,'_Confronto_Data'!$FO$2:$FO$19,'_Confronto_Data'!$FP$2:$FP$19,"")} -> 0 | C39: {=_xlfn.XLOOKUP(A39,'_Confronto_Data'!$FO$2:$FO$19,'_Confronto_Data'!$FQ$2:$FQ$19,"")} -> 0 | D39: {=_xlfn.XLOOKUP(A39,'_Confronto_Data'!$FO$2:$FO$19,'_Confronto_Data'!$FR$2:$FR$19,"")} -> 0 | E39: =IF($B$5="","",SUMIFS('_Confronto_Data'!$DQ$2:$DQ$195,'_Confronto_Data'!$DL$2:$DL$195,$B$5,'_Confronto_Data'!$DM$2:$DM$195,$A39)) -> 0 | F39: =IF($B$5="","",SUMIFS('_Confronto_Data'!$DR$2:$DR$195,'_Confronto_Data'!$DL$2:$DL$195,$B$5,'_Confronto_Data'!$DM$2:$DM$195,$A39)) -> 0 | G39: =IF($B$5="","",SUMIFS('_Confronto_Data'!$DS$2:$DS$195,'_Confronto_Data'!$DL$2:$DL$195,$B$5,'_Confronto_Data'!$DM$2:$DM$195,$A39)) -> 0 | H39: =IF($B$5="","",SUMIFS('_Confronto_Data'!$EC$2:$EC$195,'_Confronto_Data'!$DL$2:$DL$195,$B$5,'_Confronto_Data'!$DM$2:$DM$195,$A39)) -> 0 | I39: =IF($D$5="","",SUMIFS('_Confronto_Data'!$DQ$2:$DQ$195,'_Confronto_Data'!$DL$2:$DL$195,$D$5,'_Confronto_Data'!$DM$2:$DM$195,$A39)) -> 0 | J39: =IF($D$5="","",SUMIFS('_Confronto_Data'!$DR$2:$DR$195,'_Confronto_Data'!$DL$2:$DL$195,$D$5,'_Confronto_Data'!$DM$2:$DM$195,$A39)) -> 0 | K39: =IF($D$5="","",SUMIFS('_Confronto_Data'!$DS$2:$DS$195,'_Confronto_Data'!$DL$2:$DL$195,$D$5,'_Confronto_Data'!$DM$2:$DM$195,$A39)) -> 0 | L39: =IF($D$5="","",SUMIFS('_Confronto_Data'!$EC$2:$EC$195,'_Confronto_Data'!$DL$2:$DL$195,$D$5,'_Confronto_Data'!$DM$2:$DM$195,$A39)) -> 0
A40: 8 | B40: {=_xlfn.XLOOKUP(A40,'_Confronto_Data'!$FO$2:$FO$19,'_Confronto_Data'!$FP$2:$FP$19,"")} -> 0 | C40: {=_xlfn.XLOOKUP(A40,'_Confronto_Data'!$FO$2:$FO$19,'_Confronto_Data'!$FQ$2:$FQ$19,"")} -> 0 | D40: {=_xlfn.XLOOKUP(A40,'_Confronto_Data'!$FO$2:$FO$19,'_Confronto_Data'!$FR$2:$FR$19,"")} -> 0 | E40: =IF($B$5="","",SUMIFS('_Confronto_Data'!$DQ$2:$DQ$195,'_Confronto_Data'!$DL$2:$DL$195,$B$5,'_Confronto_Data'!$DM$2:$DM$195,$A40)) -> 0 | F40: =IF($B$5="","",SUMIFS('_Confronto_Data'!$DR$2:$DR$195,'_Confronto_Data'!$DL$2:$DL$195,$B$5,'_Confronto_Data'!$DM$2:$DM$195,$A40)) -> 0 | G40: =IF($B$5="","",SUMIFS('_Confronto_Data'!$DS$2:$DS$195,'_Confronto_Data'!$DL$2:$DL$195,$B$5,'_Confronto_Data'!$DM$2:$DM$195,$A40)) -> 0 | H40: =IF($B$5="","",SUMIFS('_Confronto_Data'!$EC$2:$EC$195,'_Confronto_Data'!$DL$2:$DL$195,$B$5,'_Confronto_Data'!$DM$2:$DM$195,$A40)) -> 0 | I40: =IF($D$5="","",SUMIFS('_Confronto_Data'!$DQ$2:$DQ$195,'_Confronto_Data'!$DL$2:$DL$195,$D$5,'_Confronto_Data'!$DM$2:$DM$195,$A40)) -> 0 | J40: =IF($D$5="","",SUMIFS('_Confronto_Data'!$DR$2:$DR$195,'_Confronto_Data'!$DL$2:$DL$195,$D$5,'_Confronto_Data'!$DM$2:$DM$195,$A40)) -> 0 | K40: =IF($D$5="","",SUMIFS('_Confronto_Data'!$DS$2:$DS$195,'_Confronto_Data'!$DL$2:$DL$195,$D$5,'_Confronto_Data'!$DM$2:$DM$195,$A40)) -> 0 | L40: =IF($D$5="","",SUMIFS('_Confronto_Data'!$EC$2:$EC$195,'_Confronto_Data'!$DL$2:$DL$195,$D$5,'_Confronto_Data'!$DM$2:$DM$195,$A40)) -> 0
A41: 9 | B41: {=_xlfn.XLOOKUP(A41,'_Confronto_Data'!$FO$2:$FO$19,'_Confronto_Data'!$FP$2:$FP$19,"")} -> 0 | C41: {=_xlfn.XLOOKUP(A41,'_Confronto_Data'!$FO$2:$FO$19,'_Confronto_Data'!$FQ$2:$FQ$19,"")} -> 0 | D41: {=_xlfn.XLOOKUP(A41,'_Confronto_Data'!$FO$2:$FO$19,'_Confronto_Data'!$FR$2:$FR$19,"")} -> 0 | E41: =IF($B$5="","",SUMIFS('_Confronto_Data'!$DQ$2:$DQ$195,'_Confronto_Data'!$DL$2:$DL$195,$B$5,'_Confronto_Data'!$DM$2:$DM$195,$A41)) -> 0 | F41: =IF($B$5="","",SUMIFS('_Confronto_Data'!$DR$2:$DR$195,'_Confronto_Data'!$DL$2:$DL$195,$B$5,'_Confronto_Data'!$DM$2:$DM$195,$A41)) -> 0 | G41: =IF($B$5="","",SUMIFS('_Confronto_Data'!$DS$2:$DS$195,'_Confronto_Data'!$DL$2:$DL$195,$B$5,'_Confronto_Data'!$DM$2:$DM$195,$A41)) -> 0 | H41: =IF($B$5="","",SUMIFS('_Confronto_Data'!$EC$2:$EC$195,'_Confronto_Data'!$DL$2:$DL$195,$B$5,'_Confronto_Data'!$DM$2:$DM$195,$A41)) -> 0 | I41: =IF($D$5="","",SUMIFS('_Confronto_Data'!$DQ$2:$DQ$195,'_Confronto_Data'!$DL$2:$DL$195,$D$5,'_Confronto_Data'!$DM$2:$DM$195,$A41)) -> 0 | J41: =IF($D$5="","",SUMIFS('_Confronto_Data'!$DR$2:$DR$195,'_Confronto_Data'!$DL$2:$DL$195,$D$5,'_Confronto_Data'!$DM$2:$DM$195,$A41)) -> 0 | K41: =IF($D$5="","",SUMIFS('_Confronto_Data'!$DS$2:$DS$195,'_Confronto_Data'!$DL$2:$DL$195,$D$5,'_Confronto_Data'!$DM$2:$DM$195,$A41)) -> 0 | L41: =IF($D$5="","",SUMIFS('_Confronto_Data'!$EC$2:$EC$195,'_Confronto_Data'!$DL$2:$DL$195,$D$5,'_Confronto_Data'!$DM$2:$DM$195,$A41)) -> 0
A42: 10 | B42: {=_xlfn.XLOOKUP(A42,'_Confronto_Data'!$FO$2:$FO$19,'_Confronto_Data'!$FP$2:$FP$19,"")} -> 0 | C42: {=_xlfn.XLOOKUP(A42,'_Confronto_Data'!$FO$2:$FO$19,'_Confronto_Data'!$FQ$2:$FQ$19,"")} -> 0 | D42: {=_xlfn.XLOOKUP(A42,'_Confronto_Data'!$FO$2:$FO$19,'_Confronto_Data'!$FR$2:$FR$19,"")} -> 0 | E42: =IF($B$5="","",SUMIFS('_Confronto_Data'!$DQ$2:$DQ$195,'_Confronto_Data'!$DL$2:$DL$195,$B$5,'_Confronto_Data'!$DM$2:$DM$195,$A42)) -> 0 | F42: =IF($B$5="","",SUMIFS('_Confronto_Data'!$DR$2:$DR$195,'_Confronto_Data'!$DL$2:$DL$195,$B$5,'_Confronto_Data'!$DM$2:$DM$195,$A42)) -> 0 | G42: =IF($B$5="","",SUMIFS('_Confronto_Data'!$DS$2:$DS$195,'_Confronto_Data'!$DL$2:$DL$195,$B$5,'_Confronto_Data'!$DM$2:$DM$195,$A42)) -> 0 | H42: =IF($B$5="","",SUMIFS('_Confronto_Data'!$EC$2:$EC$195,'_Confronto_Data'!$DL$2:$DL$195,$B$5,'_Confronto_Data'!$DM$2:$DM$195,$A42)) -> 0 | I42: =IF($D$5="","",SUMIFS('_Confronto_Data'!$DQ$2:$DQ$195,'_Confronto_Data'!$DL$2:$DL$195,$D$5,'_Confronto_Data'!$DM$2:$DM$195,$A42)) -> 0 | J42: =IF($D$5="","",SUMIFS('_Confronto_Data'!$DR$2:$DR$195,'_Confronto_Data'!$DL$2:$DL$195,$D$5,'_Confronto_Data'!$DM$2:$DM$195,$A42)) -> 0 | K42: =IF($D$5="","",SUMIFS('_Confronto_Data'!$DS$2:$DS$195,'_Confronto_Data'!$DL$2:$DL$195,$D$5,'_Confronto_Data'!$DM$2:$DM$195,$A42)) -> 0 | L42: =IF($D$5="","",SUMIFS('_Confronto_Data'!$EC$2:$EC$195,'_Confronto_Data'!$DL$2:$DL$195,$D$5,'_Confronto_Data'!$DM$2:$DM$195,$A42)) -> 0
A43: 11 | B43: {=_xlfn.XLOOKUP(A43,'_Confronto_Data'!$FO$2:$FO$19,'_Confronto_Data'!$FP$2:$FP$19,"")} -> 0 | C43: {=_xlfn.XLOOKUP(A43,'_Confronto_Data'!$FO$2:$FO$19,'_Confronto_Data'!$FQ$2:$FQ$19,"")} -> 0 | D43: {=_xlfn.XLOOKUP(A43,'_Confronto_Data'!$FO$2:$FO$19,'_Confronto_Data'!$FR$2:$FR$19,"")} -> 0 | E43: =IF($B$5="","",SUMIFS('_Confronto_Data'!$DQ$2:$DQ$195,'_Confronto_Data'!$DL$2:$DL$195,$B$5,'_Confronto_Data'!$DM$2:$DM$195,$A43)) -> 0 | F43: =IF($B$5="","",SUMIFS('_Confronto_Data'!$DR$2:$DR$195,'_Confronto_Data'!$DL$2:$DL$195,$B$5,'_Confronto_Data'!$DM$2:$DM$195,$A43)) -> 0 | G43: =IF($B$5="","",SUMIFS('_Confronto_Data'!$DS$2:$DS$195,'_Confronto_Data'!$DL$2:$DL$195,$B$5,'_Confronto_Data'!$DM$2:$DM$195,$A43)) -> 0 | H43: =IF($B$5="","",SUMIFS('_Confronto_Data'!$EC$2:$EC$195,'_Confronto_Data'!$DL$2:$DL$195,$B$5,'_Confronto_Data'!$DM$2:$DM$195,$A43)) -> 0 | I43: =IF($D$5="","",SUMIFS('_Confronto_Data'!$DQ$2:$DQ$195,'_Confronto_Data'!$DL$2:$DL$195,$D$5,'_Confronto_Data'!$DM$2:$DM$195,$A43)) -> 0 | J43: =IF($D$5="","",SUMIFS('_Confronto_Data'!$DR$2:$DR$195,'_Confronto_Data'!$DL$2:$DL$195,$D$5,'_Confronto_Data'!$DM$2:$DM$195,$A43)) -> 0 | K43: =IF($D$5="","",SUMIFS('_Confronto_Data'!$DS$2:$DS$195,'_Confronto_Data'!$DL$2:$DL$195,$D$5,'_Confronto_Data'!$DM$2:$DM$195,$A43)) -> 0 | L43: =IF($D$5="","",SUMIFS('_Confronto_Data'!$EC$2:$EC$195,'_Confronto_Data'!$DL$2:$DL$195,$D$5,'_Confronto_Data'!$DM$2:$DM$195,$A43)) -> 0
...

Sheet _Confronto_Data
A1: nome_movimento | C1: nome_portiere | F1: giocatore | G1: nome_standard | H1: ruolo | I1: ruolo_macro | J1: mano | K1: ruolo_base | L1: ruolo_label | M1: jolly | N1: ruoli_jolly | O1: note_ruolo | P1: partite_nel_foglio | Q1: partite_giocate_stimate | R1: gol_tot | S1: gol_media | T1: assist_tot | U1: assist_media | V1: tiri_tot | W1: tiri_media | X1: palla_rubata_tot | Y1: palla_rubata_media | Z1: et_pos_tot | AA1: et_pos_media | AB1: tr_pos_tot | AC1: tr_pos_media | AD1: parata_tot | AE1: parata_media | AF1: et_neg_tot | AG1: et_neg_media | AH1: tr_neg_tot | AI1: tr_neg_media | AJ1: palla_persa_tot | AK1: palla_persa_media | AL1: gol_subito_tot | AM1: gol_subito_media | AN1: controfallo_tot | AO1: controfallo_media | AP1: errore_tot | AQ1: errore_media | AR1: pct_parate_media | AS1: pct_tiri_media | AT1: pct_tiri_stagionale | AU1: partite_con_eventi | AV1: valutazione_totale | AW1: valutazione_grezza_totale | AX1: valutazione_media | AY1: valutazione_grezza_media | AZ1: indice_valutazione_0_100 | BI1: giocatore | BJ1: nome_standard | BK1: ruolo | BL1: ruolo_macro | BM1: mano | BN1: ruolo_base | BO1: ruolo_label | BP1: jolly | BQ1: ruoli_jolly | BR1: note_ruolo | BS1: partite_nel_foglio | BT1: partite_giocate_stimate | BU1: gol_tot | BV1: gol_media | BW1: assist_tot | BX1: assist_media | BY1: tiri_tot | BZ1: tiri_media | CA1: palla_rubata_tot | CB1: palla_rubata_media | CC1: et_pos_tot | CD1: et_pos_media | CE1: tr_pos_tot | CF1: tr_pos_media | CG1: parata_tot | CH1: parata_media | CI1: et_neg_tot | CJ1: et_neg_media | CK1: tr_neg_tot | CL1: tr_neg_media | CM1: palla_persa_tot | CN1: palla_persa_media | CO1: gol_subito_tot | CP1: gol_subito_media | CQ1: controfallo_tot | CR1: controfallo_media | CS1: errore_tot | CT1: errore_media | CU1: pct_parate_media | CV1: pct_tiri_media | CW1: pct_tiri_stagionale | CX1: partite_con_eventi | CY1: valutazione_totale | CZ1: valutazione_grezza_totale | DA1: valutazione_media | DB1: valutazione_grezza_media | DC1: indice_valutazione_0_100 | DL1: giocatore | DM1: giornata | DN1: data | DO1: avversario | DP1: casa_trasferta | DQ1: gol | DR1: assist | DS1: tiri | DT1: pct_tiri | DU1: palla_rubata | DV1: palla_persa | DW1: et_pos | DX1: et_neg | DY1: tr_pos | DZ1: tr_neg | EA1: controfallo | EB1: errore | EC1: valutazione_finale | EP1: giocatore | EQ1: giornata | ER1: data | ES1: avversario | ET1: casa_trasferta | EU1: partita_giocata_stimata_portiere | EV1: parata | EW1: gol_subito | EX1: pct_parate | EY1: assist | EZ1: errore | FA1: valutazione_finale | FC1: played_key | FD1: played_flag | FO1: giornata | FP1: data | FQ1: avversario | FR1: casa_trasferta
A2: BIGA | C2: FRANCHI | F2: BIGA | G2: BIGA | H2: movimento | I2: movimento | J2: D | K2: 4-5 | L2: mano-buona | M2: SI | N2: 1,2,4,5 | O2: principalmente 1,2,4,5 | P2: 14 | R2: 16 | S2: 1.142857 | T2: 17 | U2: 1.214286 | V2: 33 | W2: 2.357143 | X2: 11 | Y2: 0.785714 | Z2: 5 | AA2: 0.357143 | AB2: 3 | AC2: 0.214286 | AD2: 4 | AE2: 0.285714 | AF2: 6 | AG2: 0.428571 | AH2: 1 | AI2: 0.071429 | AJ2: 10 | AK2: 0.714286 | AL2: 0 | AM2: 0 | AN2: 4 | AO2: 0.285714 | AP2: 16 | AQ2: 1.142857 | AR2: 1 | AS2: 0.391026 | AT2: 0.484848 | AU2: 14 | AV2: 117 | AW2: 117 | AX2: 8.357143 | AY2: 8.357143 | AZ2: 45.36 | BI2: FRANCHI | BJ2: FRANCHI | BK2: portiere | BL2: portiere | BM2: D | BN2: GK | BO2: portiere | BP2: NO | BS2: 3 | BT2: 2 | BU2: 0 | BV2: 0 | BW2: 2 | BX2: 0.666667 | BY2: 0 | BZ2: 0 | CA2: 0 | CB2: 0 | CC2: 0 | CD2: 0 | CE2: 0 | CF2: 0 | CG2: 4 | CH2: 2 | CI2: 0 | CJ2: 0 | CK2: 0 | CL2: 0 | CM2: 0 | CN2: 0 | CO2: 5 | CP2: 2.5 | CQ2: 0 | CR2: 0 | CS2: 0 | CT2: 0 | CU2: 0.45 | CX2: 3 | CY2: 3 | CZ2: 3 | DA2: 1.5 | DB2: 1.5 | DC2: 100 | DL2: GULLO | DM2: 2 | DN2: 2026-01-17 | DO2: PN Milano 1 | DP2: Trasferta | DQ2: 1 | DR2: 1 | DS2: 4 | DV2: 2 | DX2: 1 | EA2: 1 | EC2: 1.5 | EP2: LUCA BOLO | EQ2: 2 | ER2: 2026-01-17 | ES2: PN Milano 1 | ET2: Trasferta | EU2: SI | EV2: 9 | EW2: 11 | EY2: 1 | EZ2: 0.45 | FA2: -3.9 | FC2: LUCA BOLO|2 | FD2: SI | FO2: 1 | FP2: 2026-01-10 | FQ2: Project Sport | FR2: Casa
A3: BOBBOX | C3: LUCA BOLO | F3: BOBBOX | G3: BOBBOX | H3: movimento | I3: movimento | J3: D | K3: 3 | L3: marcatore del centro | M3: NO | P3: 16 | R3: 3 | S3: 0.1875 | T3: 14 | U3: 0.875 | V3: 20 | W3: 1.25 | X3: 7 | Y3: 0.4375 | Z3: 4 | AA3: 0.25 | AB3: 1 | AC3: 0.0625 | AD3: 4 | AE3: 0.25 | AF3: 15 | AG3: 0.9375 | AH3: 3 | AI3: 0.1875 | AJ3: 11 | AK3: 0.6875 | AL3: 0 | AM3: 0 | AN3: 5 | AO3: 0.3125 | AP3: 7 | AQ3: 0.4375 | AR3: 0 | AS3: 0.133333 | AT3: 0.15 | AU3: 16 | AV3: 5.5 | AW3: 5.5 | AX3: 0.34375 | AY3: 0.34375 | AZ3: 5.54 | BI3: LUCA BOLO | BJ3: LUCA BOLO | BK3: portiere | BL3: portiere | BM3: D | BN3: GK | BO3: portiere | BP3: NO | BS3: 14 | BT3: 9 | BU3: 0 | BV3: 0 | BW3: 6 | BX3: 0.428571 | BY3: 0 | BZ3: 0 | CA3: 2 | CB3: 0.142857 | CC3: 0 | CD3: 0 | CE3: 0 | CF3: 0 | CG3: 54 | CH3: 6 | CI3: 1 | CJ3: 0.071429 | CK3: 0 | CL3: 0 | CM3: 1 | CN3: 0.071429 | CO3: 73 | CP3: 8.111111 | CQ3: 0 | CR3: 0 | CS3: 4.45 | CT3: 0.494444 | CU3: 0.372448 | CX3: 14 | CY3: -47.9 | CZ3: -47.9 | DA3: -5.322222 | DB3: -5.322222 | DC3: 0 | DL3: CRIVE A. | DM3: 2 | DN3: 2026-01-17 | DO3: PN Milano 1 | DP3: Trasferta | DQ3: 4 | DR3: 0 | DS3: 6 | DU3: 1 | DV3: 2 | DW3: 2 | DY3: 1 | EA3: 2 | EC3: 25 | EP3: SANTA | EQ3: 2 | ER3: 2026-01-17 | ES3: PN Milano 1 | ET3: Trasferta | EU3: NO | EV3: 0 | EW3: 0 | EZ3: 0 | FA3: 0 | FC3: SANTA|2 | FD3: NO | FO3: 2 | FP3: 2026-01-17 | FQ3: PN Milano 1 | FR3: Trasferta
A4: BOBBY | C4: SANTA | F4: BOBBY | G4: BOBBY | H4: movimento | I4: movimento | J4: D | K4: 4-5 | L4: mano-buona | M4: SI | N4: 4,5,6 | O4: jolly | P4: 16 | R4: 36 | S4: 2.25 | T4: 19 | U4: 1.1875 | V4: 85 | W4: 5.3125 | X4: 18 | Y4: 1.125 | Z4: 16 | AA4: 1 | AB4: 3 | AC4: 0.1875 | AD4: 9 | AE4: 0.5625 | AF4: 15 | AG4: 0.9375 | AH4: 0 | AI4: 0 | AJ4: 10 | AK4: 0.625 | AL4: 0 | AM4: 0 | AN4: 11 | AO4: 0.6875 | AP4: 12 | AQ4: 0.75 | AR4: 0 | AS4: 0.401337 | AT4: 0.423529 | AU4: 16 | AV4: 270 | AW4: 270 | AX4: 16.875 | AY4: 16.875 | AZ4: 100 | BI4: SANTA | BJ4: SANTA | BK4: portiere | BL4: portiere | BM4: S | BN4: GK | BO4: portiere | BP4: NO | BS4: 16 | BT4: 12 | BU4: 0 | BV4: 0 | BW4: 4 | BX4: 0.25 | BY4: 0 | BZ4: 0 | CA4: 0 | CB4: 0 | CC4: 0 | CD4: 0 | CE4: 0 | CF4: 0 | CG4: 82 | CH4: 6.833333 | CI4: 0 | CJ4: 0 | CK4: 0 | CL4: 0 | CM4: 0 | CN4: 0 | CO4: 86 | CP4: 7.166667 | CQ4: 0 | CR4: 0 | CS4: 3 | CT4: 0.25 | CU4: 0.43914 | CX4: 16 | CY4: -6 | CZ4: -6 | DA4: -0.5 | DB4: -0.5 | DC4: 82.32 | DL4: CRIVE L. | DM4: 2 | DN4: 2026-01-17 | DO4: PN Milano 1 | DP4: Trasferta | DR4: 3 | DS4: 1 | DU4: 1 | EA4: 1 | EC4: 9.5 | EP4: LUCA BOLO | EQ4: 3 | ER4: 2026-01-24 | ES4: CN Sestri | ET4: Casa | EU4: SI | EV4: 8 | EW4: 10 | EX4: 0.444444 | EY4: 1 | FA4: -3 | FC4: LUCA BOLO|3 | FD4: SI | FO4: 3 | FP4: 2026-01-24 | FQ4: CN Sestri | FR4: Casa
A5: CAVALLI | F5: CAVALLI | G5: CAVALLI | H5: movimento | I5: movimento | J5: D | K5: 6 | L5: centroboa | M5: NO | P5: 1 | R5: 1 | S5: 1 | T5: 0 | U5: 0 | V5: 3 | W5: 3 | X5: 0 | Y5: 0 | Z5: 0 | AA5: 0 | AB5: 1 | AC5: 1 | AD5: 0 | AE5: 0 | AF5: 0 | AG5: 0 | AH5: 0 | AI5: 0 | AJ5: 0 | AK5: 0 | AL5: 0 | AM5: 0 | AN5: 0 | AO5: 0 | AP5: 0 | AQ5: 0 | AS5: 0.333333 | AT5: 0.333333 | AU5: 1 | AV5: 9.5 | AW5: 9.5 | AX5: 9.5 | AY5: 9.5 | AZ5: 6.96 | DL5: ZENO | DM5: 2 | DN5: 2026-01-17 | DO5: PN Milano 1 | DP5: Trasferta | DQ5: 4 | DR5: 1 | DS5: 9 | DU5: 1 | DV5: 2 | DX5: 2 | EC5: 20.5 | EP5: SANTA | EQ5: 3 | ER5: 2026-01-24 | ES5: CN Sestri | ET5: Casa | EU5: NO | EX5: 0 | FA5: 0 | FC5: SANTA|3 | FD5: NO | FO5: 4 | FP5: 2026-01-31 | FQ5: SG Andrea Doria | FR5: Trasferta
A6: CRIVE A. | F6: CRIVE A. | G6: CRIVE A. | H6: movimento | I6: movimento | J6: D | K6: 6 | L6: centroboa | M6: SI | N6: 3,4,5,6 | O6: jolly | P6: 15 | R6: 22 | S6: 1.466667 | T6: 11 | U6: 0.733333 | V6: 51 | W6: 3.4 | X6: 9 | Y6: 0.6 | Z6: 33 | AA6: 2.2 | AB6: 8 | AC6: 0.533333 | AD6: 2 | AE6: 0.133333 | AF6: 12 | AG6: 0.8 | AH6: 0 | AI6: 0 | AJ6: 5 | AK6: 0.333333 | AL6: 0 | AM6: 0 | AN6: 15 | AO6: 1 | AP6: 15 | AQ6: 1 | AR6: 0.666667 | AS6: 0.382143 | AT6: 0.431373 | AU6: 15 | AV6: 195 | AW6: 195 | AX6: 13 | AY6: 13 | AZ6: 73.21 | DL6: NOA | DM6: 2 | DN6: 2026-01-17 | DO6: PN Milano 1 | DP6: Trasferta | EC6: 0 | EP6: LUCA BOLO | EQ6: 4 | ER6: 2026-01-31 | ES6: SG Andrea Doria | ET6: Trasferta | EU6: SI | EV6: 6 | EW6: 10 | EX6: 0.375 | EY6: 1 | FA6: -7 | FC6: LUCA BOLO|4 | FD6: SI | FO6: 5 | FP6: 2026-02-07 | FQ6: Busto PN | FR6: Casa
A7: CRIVE L. | F7: CRIVE L. | G7: CRIVE L. | H7: movimento | I7: movimento | J7: D | K7: 1-2 | L7: mano-cattiva | M7: NO | P7: 16 | R7: 4 | S7: 0.25 | T7: 20 | U7: 1.25 | V7: 20 | W7: 1.25 | X7: 8 | Y7: 0.5 | Z7: 7 | AA7: 0.4375 | AB7: 4 | AC7: 0.25 | AD7: 1 | AE7: 0.0625 | AF7: 11 | AG7: 0.6875 | AH7: 3 | AI7: 0.1875 | AJ7: 11 | AK7: 0.6875 | AL7: 0 | AM7: 0 | AN7: 4 | AO7: 0.25 | AP7: 7 | AQ7: 0.4375 | AR7: 0 | AS7: 0.094444 | AT7: 0.2 | AU7: 16 | AV7: 56 | AW7: 56 | AX7: 3.5 | AY7: 3.5 | AZ7: 23.57 | DL7: BIGA | DM7: 2 | DN7: 2026-01-17 | DO7: PN Milano 1 | DP7: Trasferta | DQ7: 2 | DR7: 1 | DS7: 2 | DU7: 3 | DV7: 3 | DX7: 1 | EC7: 11.5 | EP7: SANTA | EQ7: 4 | ER7: 2026-01-31 | ES7: SG Andrea Doria | ET7: Trasferta | EU7: NO | EX7: 0 | FA7: 0 | FC7: SANTA|4 | FD7: NO | FO7: 6 | FP7: 2026-02-14 | FQ7: Onda Blu Dalmine | FR7: Trasferta
A8: DONATO | F8: DONATO | G8: DONATO | H8: movimento | I8: movimento | J8: S | K8: 1-2 | L8: mano-cattiva | M8: NO | P8: 15 | R8: 15 | S8: 1 | T8: 7 | U8: 0.466667 | V8: 40 | W8: 2.666667 | X8: 17 | Y8: 1.133333 | Z8: 8 | AA8: 0.533333 | AB8: 4 | AC8: 0.266667 | AD8: 3 | AE8: 0.2 | AF8: 9 | AG8: 0.6 | AH8: 0 | AI8: 0 | AJ8: 13 | AK8: 0.866667 | AL8: 0 | AM8: 0 | AN8: 7 | AO8: 0.466667 | AP8: 3 | AQ8: 0.2 | AR8: 1 | AS8: 0.373299 | AT8: 0.375 | AU8: 15 | AV8: 116.5 | AW8: 116.5 | AX8: 7.766667 | AY8: 7.766667 | AZ8: 45.18 | DL8: BOBBY | DM8: 2 | DN8: 2026-01-17 | DO8: PN Milano 1 | DP8: Trasferta | DR8: 1 | DW8: 1 | DX8: 3 | EC8: -2 | EP8: LUCA BOLO | EQ8: 5 | ER8: 2026-02-07 | ES8: Busto PN | ET8: Casa | EU8: SI | EV8: 5 | EW8: 10 | EX8: 0.333333 | EZ8: 2 | FA8: -19 | FC8: LUCA BOLO|5 | FD8: SI | FO8: 7 | FP8: 2026-02-21 | FQ8: Bocconi Sport Team | FR8: Casa
A9: GULLO | F9: GULLO | G9: GULLO | H9: movimento | I9: movimento | J9: D | K9: 3 | L9: marcatore del centro | M9: SI | N9: 3,6 | O9: jolly | P9: 15 | R9: 16 | S9: 1.066667 | T9: 7 | U9: 0.466667 | V9: 46 | W9: 3.066667 | X9: 14 | Y9: 0.933333 | Z9: 22 | AA9: 1.466667 | AB9: 7 | AC9: 0.466667 | AD9: 6 | AE9: 0.4 | AF9: 25 | AG9: 1.666667 | AH9: 0 | AI9: 0 | AJ9: 13 | AK9: 0.866667 | AL9: 0 | AM9: 0 | AN9: 8 | AO9: 0.533333 | AP9: 9 | AQ9: 0.6 | AR9: 0.25 | AS9: 0.351361 | AT9: 0.347826 | AU9: 15 | AV9: 111.5 | AW9: 111.5 | AX9: 7.433333 | AY9: 7.433333 | AZ9: 43.39 | DL9: STERI | DM9: 2 | DN9: 2026-01-17 | DO9: PN Milano 1 | DP9: Trasferta | DQ9: 2 | DR9: 1 | DS9: 3 | DV9: 1 | DW9: 3 | DY9: 3 | EC9: 29 | EP9: SANTA | EQ9: 5 | ER9: 2026-02-07 | ES9: Busto PN | ET9: Casa | EU9: SI | EV9: 4 | EW9: 3 | EX9: 0.571429 | FA9: 3 | FC9: SANTA|5 | FD9: SI | FO9: 8 | FP9: 2026-02-28 | FQ9: PN Como | FR9: Trasferta
A10: MAPELLI | F10: MAPELLI | G10: MAPELLI | H10: movimento | I10: movimento | J10: D | K10: 4-5 | L10: mano-buona | M10: NO | P10: 1 | R10: 0 | S10: 0 | T10: 0 | U10: 0 | V10: 0 | W10: 0 | X10: 0 | Y10: 0 | Z10: 0 | AA10: 0 | AB10: 0 | AC10: 0 | AD10: 0 | AE10: 0 | AF10: 0 | AG10: 0 | AH10: 0 | AI10: 0 | AJ10: 0 | AK10: 0 | AL10: 0 | AM10: 0 | AN10: 0 | AO10: 0 | AP10: 0 | AQ10: 0 | AS10: 0 | AU10: 1 | AV10: 0 | AW10: 0 | AX10: 0 | AY10: 0 | AZ10: 3.57 | DL10: BOBBOX | DM10: 2 | DN10: 2026-01-17 | DO10: PN Milano 1 | DP10: Trasferta | DR10: 1 | DV10: 1 | DY10: 1 | EC10: 4 | EP10: LUCA BOLO | EQ10: 6 | ER10: 2026-02-14 | ES10: Onda Blu Dalmine | ET10: Trasferta | EU10: SI | EV10: 5 | EW10: 8 | EX10: 0.384615 | EZ10: 1 | FA10: -9 | FC10: LUCA BOLO|6 | FD10: SI | FO10: 9 | FP10: 2026-03-07 | FQ10: WP Novara | FR10: Casa
A11: NOA | F11: NOA | G11: NOA | H11: movimento | I11: movimento | J11: D | K11: 1-2 | L11: mano-cattiva | M11: NO | P11: 13 | R11: 10 | S11: 0.769231 | T11: 12 | U11: 0.923077 | V11: 26 | W11: 2 | X11: 9 | Y11: 0.692308 | Z11: 4 | AA11: 0.307692 | AB11: 1 | AC11: 0.076923 | AD11: 1 | AE11: 0.076923 | AF11: 5 | AG11: 0.384615 | AH11: 1 | AI11: 0.076923 | AJ11: 7 | AK11: 0.538462 | AL11: 0 | AM11: 0 | AN11: 4 | AO11: 0.307692 | AP11: 5 | AQ11: 0.384615 | AR11: 0 | AS11: 0.333333 | AT11: 0.384615 | AU11: 13 | AV11: 83.5 | AW11: 83.5 | AX11: 6.423077 | AY11: 6.423077 | AZ11: 33.39 | DL11: DONATO | DM11: 2 | DN11: 2026-01-17 | DO11: PN Milano 1 | DP11: Trasferta | DQ11: 1 | DS11: 1 | DU11: 1 | DV11: 3 | DX11: 1 | EA11: 1 | EC11: -3 | EP11: SANTA | EQ11: 6 | ER11: 2026-02-14 | ES11: Onda Blu Dalmine | ET11: Trasferta | EU11: SI | EV11: 2 | EW11: 5 | EX11: 0.285714 | FA11: -9 | FC11: SANTA|6 | FD11: SI | FO11: 10 | FP11: 2026-04-21 | FQ11: Project Sport | FR11: Trasferta
A12: PASQUA | F12: PASQUA | G12: PASQUA | H12: movimento | I12: movimento | J12: D | K12: 1-2 | L12: mano-cattiva | M12: NO | P12: 10 | R12: 0 | S12: 0 | T12: 1 | U12: 0.1 | V12: 3 | W12: 0.3 | X12: 2 | Y12: 0.2 | Z12: 1 | AA12: 0.1 | AB12: 0 | AC12: 0 | AD12: 2 | AE12: 0.2 | AF12: 4 | AG12: 0.4 | AH12: 1 | AI12: 0.1 | AJ12: 1 | AK12: 0.1 | AL12: 0 | AM12: 0 | AN12: 2 | AO12: 0.2 | AP12: 2 | AQ12: 0.2 | AR12: 0 | AS12: 0 | AT12: 0 | AU12: 10 | AV12: -10 | AW12: -10 | AX12: -1 | AY12: -1 | AZ12: 0 | DL12: SOLDI | DM12: 2 | DN12: 2026-01-17 | DO12: PN Milano 1 | DP12: Trasferta | DU12: 1 | DX12: 1 | DY12: 1 | EC12: 2.5 | EP12: LUCA BOLO | EQ12: 7 | ER12: 2026-02-21 | ES12: Bocconi Sport Team | ET12: Casa | EU12: SI | EV12: 12 | EW12: 11 | EX12: 0.521739 | EY12: 1 | FA12: 6 | FC12: LUCA BOLO|7 | FD12: SI | FO12: 11 | FP12: 2026-03-21 | FQ12: PN Milano 1 | FR12: Casa
A13: POPOVIC | F13: POPOVIC | G13: POPOVIC | H13: movimento | I13: movimento | J13: D | K13: 4-5 | L13: mano-buona | M13: NO | P13: 14 | R13: 11 | S13: 0.785714 | T13: 4 | U13: 0.285714 | V13: 27 | W13: 1.928571 | X13: 4 | Y13: 0.285714 | Z13: 2 | AA13: 0.142857 | AB13: 2 | AC13: 0.142857 | AD13: 2 | AE13: 0.142857 | AF13: 11 | AG13: 0.785714 | AH13: 1 | AI13: 0.071429 | AJ13: 4 | AK13: 0.285714 | AL13: 0 | AM13: 0 | AN13: 0 | AO13: 0 | AP13: 8 | AQ13: 0.571429 | AR13: 0 | AS13: 0.358974 | AT13: 0.407407 | AU13: 14 | AV13: 47 | AW13: 47 | AX13: 3.357143 | AY13: 3.357143 | AZ13: 20.36 | DL13: POPOVIC | DM13: 2 | DN13: 2026-01-17 | DO13: PN Milano 1 | DP13: Trasferta | DS13: 1 | EC13: 0.5 | EP13: SANTA | EQ13: 7 | ER13: 2026-02-21 | ES13: Bocconi Sport Team | ET13: Casa | EU13: NO | EX13: 0 | FA13: 0 | FC13: SANTA|7 | FD13: NO | FO13: 12 | FP13: 2026-03-28 | FQ13: CN Sestri | FR13: Trasferta
A14: SERGIO | F14: SERGIO | G14: SERGIO | H14: movimento | I14: movimento | J14: D | K14: 3 | L14: marcatore del centro | M14: NO | P14: 1 | R14: 0 | S14: 0 | T14: 1 | U14: 1 | V14: 0 | W14: 0 | X14: 0 | Y14: 0 | Z14: 0 | AA14: 0 | AB14: 0 | AC14: 0 | AD14: 0 | AE14: 0 | AF14: 0 | AG14: 0 | AH14: 0 | AI14: 0 | AJ14: 0 | AK14: 0 | AL14: 0 | AM14: 0 | AN14: 1 | AO14: 1 | AP14: 1 | AQ14: 1 | AS14: 0 | AU14: 1 | AV14: -1 | AW14: -1 | AX14: -1 | AY14: -1 | AZ14: 3.21 | DL14: PASQUA | DM14: 2 | DN14: 2026-01-17 | DO14: PN Milano 1 | DP14: Trasferta | DS14: 1 | DU14: 1 | DW14: 1 | DX14: 1 | EA14: 2 | EC14: -1.5 | EP14: SANTA | EQ14: 8 | ER14: 2026-02-28 | ES14: PN Como | ET14: Trasferta | EU14: SI | EV14: 10 | EW14: 9 | EX14: 0.526316 | FA14: 3 | FC14: SANTA|8 | FD14: SI | FO14: 13 | FP14: 2026-04-11 | FQ14: SG Andrea Doria | FR14: Casa
A15: SOLDI | F15: SOLDI | G15: SOLDI | H15: movimento | I15: movimento | J15: D | K15: 1-2 | L15: mano-cattiva | M15: NO | P15: 16 | R15: 1 | S15: 0.0625 | T15: 14 | U15: 0.875 | V15: 14 | W15: 0.875 | X15: 4 | Y15: 0.25 | Z15: 3 | AA15: 0.1875 | AB15: 5 | AC15: 0.3125 | AD15: 2 | AE15: 0.125 | AF15: 6 | AG15: 0.375 | AH15: 0 | AI15: 0 | AJ15: 2 | AK15: 0.125 | AL15: 0 | AM15: 0 | AN15: 2 | AO15: 0.125 | AP15: 6 | AQ15: 0.375 | AR15: 0 | AS15: 0.033333 | AT15: 0.071429 | AU15: 16 | AV15: 51.5 | AW15: 51.5 | AX15: 3.21875 | AY15: 3.21875 | AZ15: 21.96 | DL15: GULLO | DM15: 3 | DN15: 2026-01-24 | DO15: CN Sestri | DP15: Casa | DS15: 2 | DT15: 0 | DU15: 1 | DW15: 1 | DX15: 2 | EC15: 0.5 | EP15: FRANCHI | EQ15: 8 | ER15: 2026-02-28 | ES15: PN Como | ET15: Trasferta | EU15: NO | EX15: 0 | FA15: 0 | FC15: FRANCHI|8 | FD15: NO | FO15: 14 | FP15: 2026-04-18 | FQ15: Busto PN | FR15: Trasferta
A16: STERI | F16: STERI | G16: STERI | H16: movimento | I16: movimento | J16: D | K16: 6 | L16: centroboa | M16: NO | P16: 15 | R16: 19 | S16: 1.266667 | T16: 4 | U16: 0.266667 | V16: 33 | W16: 2.2 | X16: 5 | Y16: 0.333333 | Z16: 32 | AA16: 2.133333 | AB16: 7 | AC16: 0.466667 | AD16: 6 | AE16: 0.4 | AF16: 8 | AG16: 0.533333 | AH16: 0 | AI16: 0 | AJ16: 9 | AK16: 0.6 | AL16: 0 | AM16: 0 | AN16: 14 | AO16: 0.933333 | AP16: 5 | AQ16: 0.333333 | AR16: 0.666667 | AS16: 0.458333 | AT16: 0.575758 | AU16: 15 | AV16: 164.5 | AW16: 164.5 | AX16: 10.966667 | AY16: 10.966667 | AZ16: 62.32 | DL16: CRIVE A. | DM16: 3 | DN16: 2026-01-24 | DO16: CN Sestri | DP16: Casa | DQ16: 2 | DR16: 1 | DS16: 4 | DT16: 0.5 | DU16: 1 | DW16: 1 | DX16: 1 | EB16: 1 | EC16: 15 | EP16: LUCA BOLO | EQ16: 9 | ER16: 2026-03-07 | ES16: WP Novara | ET16: Casa | EU16: SI | EV16: 0 | EW16: 3 | EX16: 0 | EZ16: 1 | FA16: -11 | FC16: LUCA BOLO|9 | FD16: SI | FO16: 15 | FP16: 2026-05-09 | FQ16: Onda Blu Dalmine | FR16: Casa
A17: ZENO | F17: ZENO | G17: ZENO | H17: movimento | I17: movimento | J17: D | K17: 4-5 | L17: mano-buona | M17: NO | P17: 16 | R17: 57 | S17: 3.5625 | T17: 6 | U17: 0.375 | V17: 118 | W17: 7.375 | X17: 12 | Y17: 0.75 | Z17: 6 | AA17: 0.375 | AB17: 3 | AC17: 0.1875 | AD17: 4 | AE17: 0.25 | AF17: 17 | AG17: 1.0625 | AH17: 2 | AI17: 0.125 | AJ17: 21 | AK17: 1.3125 | AL17: 0 | AM17: 0 | AN17: 8 | AO17: 0.5 | AP17: 21 | AQ17: 1.3125 | AR17: 0.444444 | AS17: 0.500387 | AT17: 0.483051 | AU17: 16 | AV17: 265.5 | AW17: 265.5 | AX17: 16.59375 | AY17: 16.59375 | AZ17: 98.39 | DL17: CRIVE L. | DM17: 3 | DN17: 2026-01-24 | DO17: CN Sestri | DP17: Casa | DQ17: 1 | DR17: 2 | DS17: 4 | DT17: 0.25 | DU17: 1 | DX17: 2 | DY17: 1 | EB17: 1 | EC17: 11 | EP17: SANTA | EQ17: 9 | ER17: 2026-03-07 | ES17: WP Novara | ET17: Casa | EU17: SI | EV17: 8 | EW17: 7 | EX17: 0.533333 | EZ17: 1 | FA17: 1 | FC17: SANTA|9 | FD17: SI | FO17: 16 | FP17: 2026-05-16 | FQ17: Bocconi Sport Team | FR17: Trasferta
DL18: ZENO | DM18: 3 | DN18: 2026-01-24 | DO18: CN Sestri | DP18: Casa | DQ18: 3 | DR18: 1 | DS18: 5 | DT18: 0.6 | DX18: 1 | DZ18: 1 | EA18: 2 | EB18: 2 | EC18: 7 | EP18: SANTA | EQ18: 11 | ER18: 2026-03-21 | ES18: PN Milano 1 | ET18: Casa | EU18: SI | EV18: 7 | EW18: 9 | EX18: 0.4375 | EZ18: 1 | FA18: -8 | FC18: SANTA|11 | FD18: SI | FO18: 17 | FP18: 2026-05-23 | FQ18: PN Como | FR18: Casa
DL19: BIGA | DM19: 3 | DN19: 2026-01-24 | DO19: CN Sestri | DP19: Casa | DQ19: 1 | DS19: 1 | DT19: 1 | DU19: 1 | DW19: 1 | DY19: 1 | EB19: 3 | EC19: 7 | EP19: FRANCHI | EQ19: 11 | ER19: 2026-03-21 | ES19: PN Milano 1 | ET19: Casa | EU19: SI | EV19: 2 | EW19: 3 | EX19: 0.4 | FA19: -3 | FC19: FRANCHI|11 | FD19: SI | FO19: 18 | FP19: 2026-05-30 | FQ19: WP Novara | FR19: Trasferta
DL20: BOBBY | DM20: 3 | DN20: 2026-01-24 | DO20: CN Sestri | DP20: Casa | DQ20: 5 | DR20: 1 | DS20: 9 | DT20: 0.555556 | DU20: 4 | DW20: 1 | DX20: 1 | EA20: 2 | EB20: 2 | EC20: 32.5 | EP20: LUCA BOLO | EQ20: 13 | ER20: 2026-04-11 | ES20: SG Andrea Doria | ET20: Casa | EU20: SI | EV20: 3 | EW20: 5 | EX20: 0.375 | EY20: 1 | FA20: -3 | FC20: LUCA BOLO|13 | FD20: SI
DL21: STERI | DM21: 3 | DN21: 2026-01-24 | DO21: CN Sestri | DP21: Casa | DQ21: 1 | DS21: 2 | DT21: 0.5 | DW21: 1 | DX21: 1 | EA21: 1 | EC21: 4 | EP21: SANTA | EQ21: 13 | ER21: 2026-04-11 | ES21: SG Andrea Doria | ET21: Casa | EU21: SI | EV21: 3 | EW21: 3 | EX21: 0.5 | FA21: 0 | FC21: SANTA|13 | FD21: SI
DL22: BOBBOX | DM22: 3 | DN22: 2026-01-24 | DO22: CN Sestri | DP22: Casa | DS22: 3 | DT22: 0 | DU22: 1 | DZ22: 2 | EA22: 1 | EC22: -4.5 | EP22: LUCA BOLO | EQ22: 14 | ER22: 2026-04-18 | ES22: Busto PN | ET22: Trasferta | EU22: NO | EX22: 0 | FA22: 0 | FC22: LUCA BOLO|14 | FD22: NO
DL23: DONATO | DM23: 3 | DN23: 2026-01-24 | DO23: CN Sestri | DP23: Casa | DQ23: 2 | DR23: 2 | DS23: 3 | DT23: 0.666667 | DU23: 3 | DV23: 1 | DX23: 2 | EC23: 16.5 | EP23: SANTA | EQ23: 14 | ER23: 2026-04-18 | ES23: Busto PN | ET23: Trasferta | EU23: SI | EV23: 10 | EW23: 11 | EX23: 0.47619 | EY23: 2 | FA23: 3 | FC23: SANTA|14 | FD23: SI
DL24: SOLDI | DM24: 3 | DN24: 2026-01-24 | DO24: CN Sestri | DP24: Casa | DR24: 2 | DS24: 1 | DT24: 0 | EC24: 6.5 | EP24: LUCA BOLO | EQ24: 10 | ER24: 2026-04-21 | ES24: Project Sport | ET24: Trasferta | EU24: SI | EV24: 6 | EW24: 5 | EX24: 0.545455 | EY24: 1 | FA24: 2 | FC24: LUCA BOLO|10 | FD24: SI
DL25: POPOVIC | DM25: 3 | DN25: 2026-01-24 | DO25: CN Sestri | DP25: Casa | DT25: 0 | DX25: 2 | EC25: -5 | EP25: SANTA | EQ25: 10 | ER25: 2026-04-21 | ES25: Project Sport | ET25: Trasferta | EU25: SI | EW25: 1 | EX25: 0 | FA25: -3 | FC25: SANTA|10 | FD25: SI
DL26: PASQUA | DM26: 3 | DN26: 2026-01-24 | DO26: CN Sestri | DP26: Casa | DS26: 2 | DT26: 0 | DZ26: 1 | EC26: -2 | EP26: FRANCHI | EQ26: 10 | ER26: 2026-04-21 | ES26: Project Sport | ET26: Trasferta | EU26: SI | EV26: 2 | EW26: 2 | EX26: 0.5 | EY26: 2 | FA26: 6 | FC26: FRANCHI|10 | FD26: SI
DL27: GULLO | DM27: 4 | DN27: 2026-01-31 | DO27: SG Andrea Doria | DP27: Trasferta | DQ27: 1 | DS27: 3 | DT27: 0.333333 | DU27: 2 | EC27: 10.5 | EP27: LUCA BOLO | EQ27: 15 | ER27: 2026-05-09 | ES27: Onda Blu Dalmine | ET27: Casa | EU27: NO | EX27: 0 | FA27: 0 | FC27: LUCA BOLO|15 | FD27: NO
DL28: CRIVE A. | DM28: 4 | DN28: 2026-01-31 | DO28: SG Andrea Doria | DP28: Trasferta | DT28: 0 | DV28: 1 | DW28: 1 | DY28: 3 | EA28: 2 | EB28: 1 | EC28: 3.5 | EP28: SANTA | EQ28: 15 | ER28: 2026-05-09 | ES28: Onda Blu Dalmine | ET28: Casa | EU28: SI | EV28: 6 | EW28: 8 | EX28: 0.428571 | EY28: 2 | FA28: 0 | FC28: SANTA|15 | FD28: SI
DL29: CRIVE L. | DM29: 4 | DN29: 2026-01-31 | DO29: SG Andrea Doria | DP29: Trasferta | DR29: 1 | DS29: 2 | DT29: 0 | EC29: 4 | EP29: LUCA BOLO | EQ29: 16 | ER29: 2026-05-16 | ES29: Bocconi Sport Team | ET29: Trasferta | EU29: NO | EX29: 0 | FA29: 0 | FC29: LUCA BOLO|16 | FD29: NO
DL30: ZENO | DM30: 4 | DN30: 2026-01-31 | DO30: SG Andrea Doria | DP30: Trasferta | DQ30: 7 | DS30: 11 | DT30: 0.636364 | DU30: 1 | DV30: 3 | DX30: 1 | DY30: 1 | EB30: 1 | EC30: 35 | EP30: SANTA | EQ30: 16 | ER30: 2026-05-16 | ES30: Bocconi Sport Team | ET30: Trasferta | EU30: SI | EV30: 9 | EW30: 12 | EX30: 0.428571 | EZ30: 1 | FA30: -11 | FC30: SANTA|16 | FD30: SI
DL31: NOA | DM31: 4 | DN31: 2026-01-31 | DO31: SG Andrea Doria | DP31: Trasferta | DR31: 1 | DS31: 3 | DT31: 0 | DV31: 2 | DY31: 1 | EB31: 1 | EC31: 1.5 | EP31: LUCA BOLO | EQ31: 17 | ER31: 2026-05-23 | ES31: PN Como | ET31: Casa | EU31: NO | EX31: 0 | FA31: 0 | FC31: LUCA BOLO|17 | FD31: NO
DL32: BIGA | DM32: 4 | DN32: 2026-01-31 | DO32: SG Andrea Doria | DP32: Trasferta | DT32: 0 | DU32: 2 | DV32: 2 | DX32: 1 | EB32: 1 | EC32: -4.5 | EP32: SANTA | EQ32: 17 | ER32: 2026-05-23 | ES32: PN Como | ET32: Casa | EU32: SI | EV32: 16 | EW32: 10 | EX32: 0.615385 | FA32: 18 | FC32: SANTA|17 | FD32: SI
DL33: BOBBY | DM33: 4 | DN33: 2026-01-31 | DO33: SG Andrea Doria | DP33: Trasferta | DQ33: 1 | DR33: 1 | DS33: 4 | DT33: 0.25 | DU33: 1 | DW33: 2 | DY33: 1 | EA33: 3 | EC33: 14 | EP33: LUCA BOLO | EQ33: 18 | ER33: 2026-05-30 | ES33: WP Novara | ET33: Trasferta | EU33: NO | EX33: 0 | FA33: 0 | FC33: LUCA BOLO|18 | FD33: NO
DL34: STERI | DM34: 4 | DN34: 2026-01-31 | DO34: SG Andrea Doria | DP34: Trasferta | DQ34: 2 | DS34: 4 | DT34: 0.5 | EA34: 2 | EC34: 8 | EP34: SANTA | EQ34: 18 | ER34: 2026-05-30 | ES34: WP Novara | ET34: Trasferta | EU34: SI | EV34: 7 | EW34: 8 | EX34: 0.466667 | FA34: -3 | FC34: SANTA|18 | FD34: SI
DL35: BOBBOX | DM35: 4 | DN35: 2026-01-31 | DO35: SG Andrea Doria | DP35: Trasferta | DQ35: 1 | DR35: 2 | DS35: 1 | DT35: 1 | DV35: 1 | DX35: 2 | EC35: 4.5
DL36: DONATO | DM36: 4 | DN36: 2026-01-31 | DO36: SG Andrea Doria | DP36: Trasferta | DS36: 3 | DT36: 0 | DU36: 2 | EC36: 5.5
DL37: SOLDI | DM37: 4 | DN37: 2026-01-31 | DO37: SG Andrea Doria | DP37: Trasferta | DS37: 2 | DT37: 0 | EB37: 1 | EC37: -1
DL38: POPOVIC | DM38: 4 | DN38: 2026-01-31 | DO38: SG Andrea Doria | DP38: Trasferta | DQ38: 1 | DS38: 1 | DT38: 1 | DX38: 1 | EB38: 1 | EC38: 1
DL39: PASQUA | DM39: 4 | DN39: 2026-01-31 | DO39: SG Andrea Doria | DP39: Trasferta | DT39: 0 | EC39: 0
DL40: GULLO | DM40: 5 | DN40: 2026-02-07 | DO40: Busto PN | DP40: Casa | DQ40: 1 | DS40: 2 | DT40: 0.5 | DV40: 1 | DW40: 2 | DX40: 1 | EB40: 2 | EC40: 2.5
...

Sheet Partite
A1: match_id | B1: giornata | C1: data | D1: ora | E1: luogo | F1: avversario | G1: andata_ritorno | H1: casa_trasferta | I1: arese_gol | J1: avversario_gol | K1: esito | L1: statistiche_disponibili | M1: sheet_name_orig | N1: q1_arese | O1: q1_avversario | P1: q2_arese | Q1: q2_avversario | R1: q3_arese | S1: q3_avversario | T1: q4_arese | U1: q4_avversario | V1: parziali_quarti_disponibili
A2: G01_A_project_sport | B2: 1 | C2: 2026-01-10 | D2: 13:00 | E2: Pia Grande, Monza | F2: Project Sport | G2: A | H2: Casa | I2: 13 | J2: 10 | K2: V | L2: NO | V2: NO
A3: G02_A_pn_milano_1 | B3: 2 | C3: 2026-01-17 | D3: 20:30 | E3: Comunale, Romano di Lombardia (BG) | F3: PN Milano 1 | G3: A | H3: Trasferta | I3: 14 | J3: 11 | K3: V | L3: SI | M3: A|PN MILANO | V3: NO
A4: G03_A_cn_sestri | B4: 3 | C4: 2026-01-24 | D4: 10:00 | E4: Pia Grande, Monza | F4: CN Sestri | G4: A | H4: Casa | I4: 15 | J4: 10 | K4: V | L4: SI | M4: A|SESTRI | V4: NO
A5: G04_A_sg_andrea_doria | B5: 4 | C5: 2026-01-31 | D5: 13:00 | E5: Comunale, Sori (GE) | F5: SG Andrea Doria | G5: A | H5: Trasferta | I5: 13 | J5: 10 | K5: V | L5: SI | M5: A|DORIA | V5: NO
A6: G05_A_busto_pn | B6: 5 | C6: 2026-02-07 | D6: 19:00 | E6: Comunale, Dalmine (BG) | F6: Busto PN | G6: A | H6: Casa | I6: 11 | J6: 13 | K6: P | L6: SI | M6: A|BUSTO | V6: NO
A7: G06_A_onda_blu_dalmine | B7: 6 | C7: 2026-02-14 | D7: 21:00 | E7: Pia Grande, Monza | F7: Onda Blu Dalmine | G7: A | H7: Trasferta | I7: 7 | J7: 13 | K7: P | L7: SI | M7: A|ONDABLU | V7: NO
